Workbook
Name a_ann_06: 'Pricing Term Assurance'!$C$7
Name a_ann_12: 'Pricing Term Assurance'!$C$18
Name a_asure_06: 'Pricing Term Assurance'!$C$8
Name a_asure_12: 'Pricing Term Assurance'!$C$19
Name b_ann_06: 'Pricing Term Assurance'!$F$7
Name b_ann_12: 'Pricing Term Assurance'!$F$18
Name b_asure_06: 'Pricing Term Assurance'!$F$8
Name b_asure_12: 'Pricing Term Assurance'!$F$19
Name c_ann_06: 'Pricing Term Assurance'!$I$7
Name c_ann_12: 'Pricing Term Assurance'!$I$18
Name c_asure_06: 'Pricing Term Assurance'!$I$8
Name c_asure_12: 'Pricing Term Assurance'!$I$19
Name d_ann_06: 'Pricing Term Assurance'!$L$7
Name d_ann_12: 'Pricing Term Assurance'!$L$18
Name d_asure_06: 'Pricing Term Assurance'!$L$8
Name d_asure_12: 'Pricing Term Assurance'!$L$19
Name e_ann_06: 'Pricing Term Assurance'!$O$7
Name e_ann_12: 'Pricing Term Assurance'!$O$18
Name e_asure_06: 'Pricing Term Assurance'!$O$8
Name e_asure_12: 'Pricing Term Assurance'!$O$19
Name i: Calculations!$C$11
Name in_com: Calculations!$C$19
Name in_exp: Calculations!$C$14
Name re_com: Calculations!$C$21
Name re_exp: Calculations!$C$17
Name sum_assured: Calculations!$C$9
Name v: Calculations!$C$12

Sheet IALM Comparison
J2: Sign interpretation | AE2: IALM (2006-08) | AL2: IALM (2012-14)
J3: " + " = Improved
B4: Age | C4: IALM 2006-08 | D4: IALM 2012-14 | F4: Age | G4: Improvement | H4: Status | J4: " - " = Deteriorated | AE4: Age | AJ4: Force | AL4: Age | AQ4: Force
B5: 2 | C5: 0.002935 | D5: 0.000915 | F5: 2 | G5: =(C5-D5)/C5 -> 0.68824532 | H5: =IF(G5>0,"Improved","Deteriorated") -> Improved | AE5: 2 | AF5: 0.002935 | AG5: =10000 -> 10000 | AH5: =AG5*AF5 -> 29.35 | AI5: =1-AF5 -> 0.997065 | AJ5: =-LN(AI5) -> 0.0029393156 | AL5: 2 | AM5: 0.000915 | AN5: =10000 -> 10000 | AO5: =AN5*AM5 -> 9.15 | AP5: =1-AM5 -> 0.999085 | AQ5: =IFERROR(-LN(AP5),"N/A") -> 0.00091541887
B6: 3 | C6: 0.002212 | D6: 0.00047 | F6: 3 | G6: =(C6-D6)/C6 -> 0.7875226 | H6: =IF(G6>0,"Improved","Deteriorated") -> Improved | R6: Row Labels | S6: Average of Improvement | AE6: 3 | AF6: 0.002212 | AG6: =AG5-AH5 -> 9970.65 | AH6: =AG6*AF6 -> 22.055078 | AI6: =1-AF6 -> 0.997788 | AJ6: =-LN(AI6) -> 0.0022144501 | AL6: 3 | AM6: 0.00047 | AN6: =AN5-AO5 -> 9990.85 | AO6: =AN6*AM6 -> 4.6956995 | AP6: =1-AM6 -> 0.99953 | AQ6: =IFERROR(-LN(AP6),"N/A") -> 0.00047011048
B7: 4 | C7: 0.00167 | D7: 0.000271 | F7: 4 | G7: =(C7-D7)/C7 -> 0.83772455 | H7: =IF(G7>0,"Improved","Deteriorated") -> Improved | R7: 0-9 | S7: 0.76344403 | AE7: 4 | AF7: 0.00167 | AG7: =AG6-AH6 -> 9948.5949 | AH7: =AG7*AF7 -> 16.614154 | AI7: =1-AF7 -> 0.99833 | AJ7: =-LN(AI7) -> 0.001671396 | AL7: 4 | AM7: 0.000271 | AN7: =AN6-AO6 -> 9986.1543 | AO7: =AN7*AM7 -> 2.7062478 | AP7: =1-AM7 -> 0.999729 | AQ7: =IFERROR(-LN(AP7),"N/A") -> 0.00027103673
B8: 5 | C8: 0.001265 | D8: 0.000185 | F8: 5 | G8: =(C8-D8)/C8 -> 0.85375494 | H8: =IF(G8>0,"Improved","Deteriorated") -> Improved | R8: 10-19 | S8: -0.0082749238 | AE8: 5 | AF8: 0.001265 | AG8: =AG7-AH7 -> 9931.9808 | AH8: =AG8*AF8 -> 12.563956 | AI8: =1-AF8 -> 0.998735 | AJ8: =-LN(AI8) -> 0.0012658008 | AL8: 5 | AM8: 0.000185 | AN8: =AN7-AO7 -> 9983.4481 | AO8: =AN8*AM8 -> 1.8469379 | AP8: =1-AM8 -> 0.999815 | AQ8: =IFERROR(-LN(AP8),"N/A") -> 0.00018501711
B9: 6 | C9: 0.000964 | D9: 0.000152 | F9: 6 | G9: =(C9-D9)/C9 -> 0.84232365 | H9: =IF(G9>0,"Improved","Deteriorated") -> Improved | R9: 20-29 | S9: 0.035375377 | AE9: 6 | AF9: 0.000964 | AG9: =AG8-AH8 -> 9919.4168 | AH9: =AG9*AF9 -> 9.5623178 | AI9: =1-AF9 -> 0.999036 | AJ9: =-LN(AI9) -> 0.00096446495 | AL9: 6 | AM9: 0.000152 | AN9: =AN8-AO8 -> 9981.6011 | AO9: =AN9*AM9 -> 1.5172034 | AP9: =1-AM9 -> 0.999848 | AQ9: =IFERROR(-LN(AP9),"N/A") -> 0.00015201155
B10: 7 | C10: 0.000744 | D10: 0.000149 | F10: 7 | G10: =(C10-D10)/C10 -> 0.79973118 | H10: =IF(G10>0,"Improved","Deteriorated") -> Improved | R10: 30-39 | S10: 0.065874098 | AE10: 7 | AF10: 0.000744 | AG10: =AG9-AH9 -> 9909.8545 | AH10: =AG10*AF10 -> 7.3729317 | AI10: =1-AF10 -> 0.999256 | AJ10: =-LN(AI10) -> 0.00074427691 | AL10: 7 | AM10: 0.000149 | AN10: =AN9-AO9 -> 9980.0839 | AO10: =AN10*AM10 -> 1.4870325 | AP10: =1-AM10 -> 0.999851 | AQ10: =IFERROR(-LN(AP10),"N/A") -> 0.0001490111
B11: 8 | C11: 0.00059 | D11: 0.000167 | F11: 8 | G11: =(C11-D11)/C11 -> 0.71694915 | H11: =IF(G11>0,"Improved","Deteriorated") -> Improved | R11: 40-49 | S11: 0.094925222 | AE11: 8 | AF11: 0.00059 | AG11: =AG10-AH10 -> 9902.4816 | AH11: =AG11*AF11 -> 5.8424641 | AI11: =1-AF11 -> 0.99941 | AJ11: =-LN(AI11) -> 0.00059017412 | AL11: 8 | AM11: 0.000167 | AN11: =AN10-AO10 -> 9978.5969 | AO11: =AN11*AM11 -> 1.6664257 | AP11: =1-AM11 -> 0.999833 | AQ11: =IFERROR(-LN(AP11),"N/A") -> 0.00016701395
B12: 9 | C12: 0.000492 | D12: 0.000206 | F12: 9 | G12: =(C12-D12)/C12 -> 0.58130081 | H12: =IF(G12>0,"Improved","Deteriorated") -> Improved | R12: 50-59 | S12: 0.058660597 | AE12: 9 | AF12: 0.000492 | AG12: =AG11-AH11 -> 9896.6391 | AH12: =AG12*AF12 -> 4.8691464 | AI12: =1-AF12 -> 0.999508 | AJ12: =-LN(AI12) -> 0.00049212107 | AL12: 9 | AM12: 0.000206 | AN12: =AN11-AO11 -> 9976.9305 | AO12: =AN12*AM12 -> 2.0552477 | AP12: =1-AM12 -> 0.999794 | AQ12: =IFERROR(-LN(AP12),"N/A") -> 0.00020602122
B13: 10 | C13: 0.00044 | D13: 0.000265 | F13: 10 | G13: =(C13-D13)/C13 -> 0.39772727 | H13: =IF(G13>0,"Improved","Deteriorated") -> Improved | R13: 60-69 | S13: 0.056731292 | AE13: 10 | AF13: 0.00044 | AG13: =AG12-AH12 -> 9891.77 | AH13: =AG13*AF13 -> 4.3523788 | AI13: =1-AF13 -> 0.99956 | AJ13: =-LN(AI13) -> 0.00044009683 | AL13: 10 | AM13: 0.000265 | AN13: =AN12-AO12 -> 9974.8752 | AO13: =AN13*AM13 -> 2.6433419 | AP13: =1-AM13 -> 0.999735 | AQ13: =IFERROR(-LN(AP13),"N/A") -> 0.00026503512
B14: 11 | C14: 0.000428 | D14: 0.000341 | F14: 11 | G14: =(C14-D14)/C14 -> 0.20327103 | H14: =IF(G14>0,"Improved","Deteriorated") -> Improved | R14: 70-79 | S14: 0.036093727 | AE14: 11 | AF14: 0.000428 | AG14: =AG13-AH13 -> 9887.4176 | AH14: =AG14*AF14 -> 4.2318147 | AI14: =1-AF14 -> 0.999572 | AJ14: =-LN(AI14) -> 0.00042809162 | AL14: 11 | AM14: 0.000341 | AN14: =AN13-AO13 -> 9972.2319 | AO14: =AN14*AM14 -> 3.4005311 | AP14: =1-AM14 -> 0.999659 | AQ14: =IFERROR(-LN(AP14),"N/A") -> 0.00034105815
B15: 12 | C15: 0.000448 | D15: 0.000429 | F15: 12 | G15: =(C15-D15)/C15 -> 0.042410714 | H15: =IF(G15>0,"Improved","Deteriorated") -> Improved | R15: 80-89 | S15: -0.09104413 | AE15: 12 | AF15: 0.000448 | AG15: =AG14-AH14 -> 9883.1858 | AH15: =AG15*AF15 -> 4.4276672 | AI15: =1-AF15 -> 0.999552 | AJ15: =-LN(AI15) -> 0.00044810038 | AL15: 12 | AM15: 0.000429 | AN15: =AN14-AO14 -> 9968.8313 | AO15: =AN15*AM15 -> 4.2766286 | AP15: =1-AM15 -> 0.999571 | AQ15: =IFERROR(-LN(AP15),"N/A") -> 0.00042909205
B16: 13 | C16: 0.000491 | D16: 0.000522 | F16: 13 | G16: =(C16-D16)/C16 -> -0.063136456 | H16: =IF(G16>0,"Improved","Deteriorated") -> Deteriorated | R16: 90-99 | S16: -0.23391 | AE16: 13 | AF16: 0.000491 | AG16: =AG15-AH15 -> 9878.7581 | AH16: =AG16*AF16 -> 4.8504702 | AI16: =1-AF16 -> 0.999509 | AJ16: =-LN(AI16) -> 0.00049112058 | AL16: 13 | AM16: 0.000522 | AN16: =AN15-AO15 -> 9964.5547 | AO16: =AN16*AM16 -> 5.2014976 | AP16: =1-AM16 -> 0.999478 | AQ16: =IFERROR(-LN(AP16),"N/A") -> 0.00052213629
B17: 14 | C17: 0.000549 | D17: 0.000614 | F17: 14 | G17: =(C17-D17)/C17 -> -0.11839709 | H17: =IF(G17>0,"Improved","Deteriorated") -> Deteriorated | R17: 100-109 | S17: -0.23972193 | AE17: 14 | AF17: 0.000549 | AG17: =AG16-AH16 -> 9873.9076 | AH17: =AG17*AF17 -> 5.4207753 | AI17: =1-AF17 -> 0.999451 | AJ17: =-LN(AI17) -> 0.00054915076 | AL17: 14 | AM17: 0.000614 | AN17: =AN16-AO16 -> 9959.3532 | AO17: =AN17*AM17 -> 6.1150429 | AP17: =1-AM17 -> 0.999386 | AQ17: =IFERROR(-LN(AP17),"N/A") -> 0.00061418858
B18: 15 | C18: 0.000614 | D18: 0.000698 | F18: 15 | G18: =(C18-D18)/C18 -> -0.13680782 | H18: =IF(G18>0,"Improved","Deteriorated") -> Deteriorated | R18: 110-119 | S18: -0.074115208 | AE18: 15 | AF18: 0.000614 | AG18: =AG17-AH17 -> 9868.4868 | AH18: =AG18*AF18 -> 6.0592509 | AI18: =1-AF18 -> 0.999386 | AJ18: =-LN(AI18) -> 0.00061418858 | AL18: 15 | AM18: 0.000698 | AN18: =AN17-AO17 -> 9953.2382 | AO18: =AN18*AM18 -> 6.9473602 | AP18: =1-AM18 -> 0.999302 | AQ18: =IFERROR(-LN(AP18),"N/A") -> 0.00069824372
B19: 16 | C19: 0.00068 | D19: 0.00077 | F19: 16 | G19: =(C19-D19)/C19 -> -0.13235294 | H19: =IF(G19>0,"Improved","Deteriorated") -> Deteriorated | R19: Grand Total | S19: 0.029911879 | AE19: 16 | AF19: 0.00068 | AG19: =AG18-AH18 -> 9862.4276 | AH19: =AG19*AF19 -> 6.7064508 | AI19: =1-AF19 -> 0.99932 | AJ19: =-LN(AI19) -> 0.0006802313 | AL19: 16 | AM19: 0.00077 | AN19: =AN18-AO18 -> 9946.2908 | AO19: =AN19*AM19 -> 7.6586439 | AP19: =1-AM19 -> 0.99923 | AQ19: =IFERROR(-LN(AP19),"N/A") -> 0.0007702966
B20: 17 | C20: 0.000743 | D20: 0.000829 | F20: 17 | G20: =(C20-D20)/C20 -> -0.11574697 | H20: =IF(G20>0,"Improved","Deteriorated") -> Deteriorated | AE20: 17 | AF20: 0.000743 | AG20: =AG19-AH19 -> 9855.7211 | AH20: =AG20*AF20 -> 7.3228008 | AI20: =1-AF20 -> 0.999257 | AJ20: =-LN(AI20) -> 0.00074327616 | AL20: 17 | AM20: 0.000829 | AN20: =AN19-AO19 -> 9938.6322 | AO20: =AN20*AM20 -> 8.2391261 | AP20: =1-AM20 -> 0.999171 | AQ20: =IFERROR(-LN(AP20),"N/A") -> 0.00082934381
B21: 18 | C21: 0.0008 | D21: 0.000874 | F21: 18 | G21: =(C21-D21)/C21 -> -0.0925 | H21: =IF(G21>0,"Improved","Deteriorated") -> Deteriorated | AE21: 18 | AF21: 0.0008 | AG21: =AG20-AH20 -> 9848.3983 | AH21: =AG21*AF21 -> 7.8787187 | AI21: =1-AF21 -> 0.9992 | AJ21: =-LN(AI21) -> 0.00080032017 | AL21: 18 | AM21: 0.000874 | AN21: =AN20-AO20 -> 9930.393 | AO21: =AN21*AM21 -> 8.6791635 | AP21: =1-AM21 -> 0.999126 | AQ21: =IFERROR(-LN(AP21),"N/A") -> 0.00087438216
B22: 19 | C22: 0.000848 | D22: 0.000905 | F22: 19 | G22: =(C22-D22)/C22 -> -0.067216981 | H22: =IF(G22>0,"Improved","Deteriorated") -> Deteriorated | U22: Age | AE22: 19 | AF22: 0.000848 | AG22: =AG21-AH21 -> 9840.5196 | AH22: =AG22*AF22 -> 8.3447606 | AI22: =1-AF22 -> 0.999152 | AJ22: =-LN(AI22) -> 0.00084835976 | AL22: 19 | AM22: 0.000905 | AN22: =AN21-AO21 -> 9921.7139 | AO22: =AN22*AM22 -> 8.9791511 | AP22: =1-AM22 -> 0.999095 | AQ22: =IFERROR(-LN(AP22),"N/A") -> 0.00090540976
B23: 20 | C23: 0.000888 | D23: 0.000924 | F23: 20 | G23: =(C23-D23)/C23 -> -0.040540541 | H23: =IF(G23>0,"Improved","Deteriorated") -> Deteriorated | R23: Maximum Improvement | T23: =MAX(G5:G118) -> 0.85375494 | U23: =INDEX($F$5:$F$118,MATCH(T23,$G$5:$G$118,0),1) -> 5 | AE23: 20 | AF23: 0.000888 | AG23: =AG22-AH22 -> 9832.1749 | AH23: =AG23*AF23 -> 8.7309713 | AI23: =1-AF23 -> 0.999112 | AJ23: =-LN(AI23) -> 0.00088839451 | AL23: 20 | AM23: 0.000924 | AN23: =AN22-AO22 -> 9912.7347 | AO23: =AN23*AM23 -> 9.1593669 | AP23: =1-AM23 -> 0.999076 | AQ23: =IFERROR(-LN(AP23),"N/A") -> 0.00092442715
B24: 21 | C24: 0.000919 | D24: 0.000934 | F24: 21 | G24: =(C24-D24)/C24 -> -0.016322089 | H24: =IF(G24>0,"Improved","Deteriorated") -> Deteriorated | R24: Minimum Improvement | T24: =MIN(G5:G118) -> -0.27630701 | U24: =INDEX($F$5:$F$118,MATCH(T24,$G$5:$G$118,0),1) -> 100 | AE24: 21 | AF24: 0.000919 | AG24: =AG23-AH23 -> 9823.4439 | AH24: =AG24*AF24 -> 9.0277449 | AI24: =1-AF24 -> 0.999081 | AJ24: =-LN(AI24) -> 0.00091942254 | AL24: 21 | AM24: 0.000934 | AN24: =AN23-AO23 -> 9903.5754 | AO24: =AN24*AM24 -> 9.2499394 | AP24: =1-AM24 -> 0.999066 | AQ24: =IFERROR(-LN(AP24),"N/A") -> 0.00093443645
B25: 22 | C25: 0.000943 | D25: 0.000937 | F25: 22 | G25: =(C25-D25)/C25 -> 0.0063626723 | H25: =IF(G25>0,"Improved","Deteriorated") -> Improved | AE25: 22 | AF25: 0.000943 | AG25: =AG24-AH24 -> 9814.4161 | AH25: =AG25*AF25 -> 9.2549944 | AI25: =1-AF25 -> 0.999057 | AJ25: =-LN(AI25) -> 0.0009434449 | AL25: 22 | AM25: 0.000937 | AN25: =AN24-AO24 -> 9894.3254 | AO25: =AN25*AM25 -> 9.2709829 | AP25: =1-AM25 -> 0.999063 | AQ25: =IFERROR(-LN(AP25),"N/A") -> 0.00093743926
B26: 23 | C26: 0.000961 | D26: 0.000936 | F26: 23 | G26: =(C26-D26)/C26 -> 0.026014568 | H26: =IF(G26>0,"Improved","Deteriorated") -> Improved | R26: The ages 0-9 show extremely large improvements and may distort averages due to low mortality rates and differences in age definitions between the two investigations | AE26: 23 | AF26: 0.000961 | AG26: =AG25-AH25 -> 9805.1612 | AH26: =AG26*AF26 -> 9.4227599 | AI26: =1-AF26 -> 0.999039 | AJ26: =-LN(AI26) -> 0.00096146206 | AL26: 23 | AM26: 0.000936 | AN26: =AN25-AO25 -> 9885.0544 | AO26: =AN26*AM26 -> 9.2524109 | AP26: =1-AM26 -> 0.999064 | AQ26: =IFERROR(-LN(AP26),"N/A") -> 0.00093643832
B27: 24 | C27: 0.000974 | D27: 0.000933 | F27: 24 | G27: =(C27-D27)/C27 -> 0.042094456 | H27: =IF(G27>0,"Improved","Deteriorated") -> Improved | AE27: 24 | AF27: 0.000974 | AG27: =AG26-AH26 -> 9795.7384 | AH27: =AG27*AF27 -> 9.5410492 | AI27: =1-AF27 -> 0.999026 | AJ27: =-LN(AI27) -> 0.00097447465 | AL27: 24 | AM27: 0.000933 | AN27: =AN26-AO26 -> 9875.802 | AO27: =AN27*AM27 -> 9.2141233 | AP27: =1-AM27 -> 0.999067 | AQ27: =IFERROR(-LN(AP27),"N/A") -> 0.00093343552
B28: 25 | C28: 0.000984 | D28: 0.000931 | F28: 25 | G28: =(C28-D28)/C28 -> 0.053861789 | H28: =IF(G28>0,"Improved","Deteriorated") -> Improved | AE28: 25 | AF28: 0.000984 | AG28: =AG27-AH27 -> 9786.1973 | AH28: =AG28*AF28 -> 9.6296182 | AI28: =1-AF28 -> 0.999016 | AJ28: =-LN(AI28) -> 0.00098448445 | AL28: 25 | AM28: 0.000931 | AN28: =AN27-AO27 -> 9866.5879 | AO28: =AN28*AM28 -> 9.1857933 | AP28: =1-AM28 -> 0.999069 | AQ28: =IFERROR(-LN(AP28),"N/A") -> 0.00093143365
B29: 26 | C29: 0.000994 | D29: 0.000931 | F29: 26 | G29: =(C29-D29)/C29 -> 0.063380282 | H29: =IF(G29>0,"Improved","Deteriorated") -> Improved | R29: The more interesting ages for pricing are 20-70 | AE29: 26 | AF29: 0.000994 | AG29: =AG28-AH28 -> 9776.5677 | AH29: =AG29*AF29 -> 9.7179083 | AI29: =1-AF29 -> 0.999006 | AJ29: =-LN(AI29) -> 0.00099449435 | AL29: 26 | AM29: 0.000931 | AN29: =AN28-AO28 -> 9857.4021 | AO29: =AN29*AM29 -> 9.1772414 | AP29: =1-AM29 -> 0.999069 | AQ29: =IFERROR(-LN(AP29),"N/A") -> 0.00093143365
B30: 27 | C30: 0.001004 | D30: 0.000934 | F30: 27 | G30: =(C30-D30)/C30 -> 0.069721116 | H30: =IF(G30>0,"Improved","Deteriorated") -> Improved | AE30: 27 | AF30: 0.001004 | AG30: =AG29-AH29 -> 9766.8498 | AH30: =AG30*AF30 -> 9.8059172 | AI30: =1-AF30 -> 0.998996 | AJ30: =-LN(AI30) -> 0.0010045043 | AL30: 27 | AM30: 0.000934 | AN30: =AN29-AO29 -> 9848.2249 | AO30: =AN30*AM30 -> 9.198242 | AP30: =1-AM30 -> 0.999066 | AQ30: =IFERROR(-LN(AP30),"N/A") -> 0.00093443645
B31: 28 | C31: 0.001017 | D31: 0.000942 | F31: 28 | G31: =(C31-D31)/C31 -> 0.073746313 | H31: =IF(G31>0,"Improved","Deteriorated") -> Improved | AE31: 28 | AF31: 0.001017 | AG31: =AG30-AH30 -> 9757.0439 | AH31: =AG31*AF31 -> 9.9229136 | AI31: =1-AF31 -> 0.998983 | AJ31: =-LN(AI31) -> 0.0010175175 | AL31: 28 | AM31: 0.000942 | AN31: =AN30-AO30 -> 9839.0266 | AO31: =AN31*AM31 -> 9.2683631 | AP31: =1-AM31 -> 0.999058 | AQ31: =IFERROR(-LN(AP31),"N/A") -> 0.00094244396
B32: 29 | C32: 0.001034 | D32: 0.000956 | F32: 29 | G32: =(C32-D32)/C32 -> 0.075435203 | H32: =IF(G32>0,"Improved","Deteriorated") -> Improved | AE32: 29 | AF32: 0.001034 | AG32: =AG31-AH31 -> 9747.121 | AH32: =AG32*AF32 -> 10.078523 | AI32: =1-AF32 -> 0.998966 | AJ32: =-LN(AI32) -> 0.0010345349 | AL32: 29 | AM32: 0.000956 | AN32: =AN31-AO31 -> 9829.7583 | AO32: =AN32*AM32 -> 9.3972489 | AP32: =1-AM32 -> 0.999044 | AQ32: =IFERROR(-LN(AP32),"N/A") -> 0.00095645726
B33: 30 | C33: 0.001056 | D33: 0.000977 | F33: 30 | G33: =(C33-D33)/C33 -> 0.074810606 | H33: =IF(G33>0,"Improved","Deteriorated") -> Improved | AE33: 30 | AF33: 0.001056 | AG33: =AG32-AH32 -> 9737.0425 | AH33: =AG33*AF33 -> 10.282317 | AI33: =1-AF33 -> 0.998944 | AJ33: =-LN(AI33) -> 0.001056558 | AL33: 30 | AM33: 0.000977 | AN33: =AN32-AO32 -> 9820.361 | AO33: =AN33*AM33 -> 9.5944927 | AP33: =1-AM33 -> 0.999023 | AQ33: =IFERROR(-LN(AP33),"N/A") -> 0.00097747758
B34: 31 | C34: 0.001084 | D34: 0.001005 | F34: 31 | G34: =(C34-D34)/C34 -> 0.072878229 | H34: =IF(G34>0,"Improved","Deteriorated") -> Improved | AE34: 31 | AF34: 0.001084 | AG34: =AG33-AH33 -> 9726.7601 | AH34: =AG34*AF34 -> 10.543808 | AI34: =1-AF34 -> 0.998916 | AJ34: =-LN(AI34) -> 0.001084588 | AL34: 31 | AM34: 0.001005 | AN34: =AN33-AO33 -> 9810.7665 | AO34: =AN34*AM34 -> 9.8598203 | AP34: =1-AM34 -> 0.998995 | AQ34: =IFERROR(-LN(AP34),"N/A") -> 0.0010055054
B35: 32 | C35: 0.001119 | D35: 0.001042 | F35: 32 | G35: =(C35-D35)/C35 -> 0.068811439 | H35: =IF(G35>0,"Improved","Deteriorated") -> Improved | AE35: 32 | AF35: 0.001119 | AG35: =AG34-AH34 -> 9716.2163 | AH35: =AG35*AF35 -> 10.872446 | AI35: =1-AF35 -> 0.998881 | AJ35: =-LN(AI35) -> 0.0011196265 | AL35: 32 | AM35: 0.001042 | AN35: =AN34-AO34 -> 9800.9067 | AO35: =AN35*AM35 -> 10.212545 | AP35: =1-AM35 -> 0.998958 | AQ35: =IFERROR(-LN(AP35),"N/A") -> 0.0010425433
B36: 33 | C36: 0.001164 | D36: 0.001086 | F36: 33 | G36: =(C36-D36)/C36 -> 0.067010309 | H36: =IF(G36>0,"Improved","Deteriorated") -> Improved | AE36: 33 | AF36: 0.001164 | AG36: =AG35-AH35 -> 9705.3439 | AH36: =AG36*AF36 -> 11.29702 | AI36: =1-AF36 -> 0.998836 | AJ36: =-LN(AI36) -> 0.001164678 | AL36: 33 | AM36: 0.001086 | AN36: =AN35-AO35 -> 9790.6941 | AO36: =AN36*AM36 -> 10.632694 | AP36: =1-AM36 -> 0.998914 | AQ36: =IFERROR(-LN(AP36),"N/A") -> 0.0010865901
B37: 34 | C37: 0.001218 | D37: 0.00114 | F37: 34 | G37: =(C37-D37)/C37 -> 0.064039409 | H37: =IF(G37>0,"Improved","Deteriorated") -> Improved | AE37: 34 | AF37: 0.001218 | AG37: =AG36-AH36 -> 9694.0469 | AH37: =AG37*AF37 -> 11.807349 | AI37: =1-AF37 -> 0.998782 | AJ37: =-LN(AI37) -> 0.0012187424 | AL37: 34 | AM37: 0.00114 | AN37: =AN36-AO36 -> 9780.0615 | AO37: =AN37*AM37 -> 11.14927 | AP37: =1-AM37 -> 0.99886 | AQ37: =IFERROR(-LN(AP37),"N/A") -> 0.0011406503
B38: 35 | C38: 0.001282 | D38: 0.001202 | F38: 35 | G38: =(C38-D38)/C38 -> 0.062402496 | H38: =IF(G38>0,"Improved","Deteriorated") -> Improved | AE38: 35 | AF38: 0.001282 | AG38: =AG37-AH37 -> 9682.2395 | AH38: =AG38*AF38 -> 12.412631 | AI38: =1-AF38 -> 0.998718 | AJ38: =-LN(AI38) -> 0.0012828225 | AL38: 35 | AM38: 0.001202 | AN38: =AN37-AO37 -> 9768.9122 | AO38: =AN38*AM38 -> 11.742232 | AP38: =1-AM38 -> 0.998798 | AQ38: =IFERROR(-LN(AP38),"N/A") -> 0.001202723
B39: 36 | C39: 0.001358 | D39: 0.001275 | F39: 36 | G39: =(C39-D39)/C39 -> 0.061119293 | H39: =IF(G39>0,"Improved","Deteriorated") -> Improved | AE39: 36 | AF39: 0.001358 | AG39: =AG38-AH38 -> 9669.8269 | AH39: =AG39*AF39 -> 13.131625 | AI39: =1-AF39 -> 0.998642 | AJ39: =-LN(AI39) -> 0.0013589229 | AL39: 36 | AM39: 0.001275 | AN39: =AN38-AO38 -> 9757.17 | AO39: =AN39*AM39 -> 12.440392 | AP39: =1-AM39 -> 0.998725 | AQ39: =IFERROR(-LN(AP39),"N/A") -> 0.0012758135
B40: 37 | C40: 0.001447 | D40: 0.001358 | F40: 37 | G40: =(C40-D40)/C40 -> 0.061506565 | H40: =IF(G40>0,"Improved","Deteriorated") -> Improved | AE40: 37 | AF40: 0.001447 | AG40: =AG39-AH39 -> 9656.6953 | AH40: =AG40*AF40 -> 13.973238 | AI40: =1-AF40 -> 0.998553 | AJ40: =-LN(AI40) -> 0.0014480479 | AL40: 37 | AM40: 0.001358 | AN40: =AN39-AO39 -> 9744.7296 | AO40: =AN40*AM40 -> 13.233343 | AP40: =1-AM40 -> 0.998642 | AQ40: =IFERROR(-LN(AP40),"N/A") -> 0.0013589229
B41: 38 | C41: 0.001549 | D41: 0.001453 | F41: 38 | G41: =(C41-D41)/C41 -> 0.061975468 | H41: =IF(G41>0,"Improved","Deteriorated") -> Improved | AE41: 38 | AF41: 0.001549 | AG41: =AG40-AH40 -> 9642.722 | AH41: =AG41*AF41 -> 14.936576 | AI41: =1-AF41 -> 0.998451 | AJ41: =-LN(AI41) -> 0.0015502009 | AL41: 38 | AM41: 0.001453 | AN41: =AN40-AO40 -> 9731.4962 | AO41: =AN41*AM41 -> 14.139864 | AP41: =1-AM41 -> 0.998547 | AQ41: =IFERROR(-LN(AP41),"N/A") -> 0.0014540566
...

Sheet Calculations
B2: Policyholder | C2: Product | D2: Benefit | E2: Term | F2: Age | G2: Premium | I2: Using Equivalence Principle, EPV Premium = EPV Benefit + EPV Expenses and Comission
B3: A | C3: Term Assurance | D3: Immediate | E3: 10 | F3: 25 | G3: Advance
B4: B | C4: Term Assurance | D4: Immediate | E4: 10 | F4: 30 | G4: Advance
B5: C | C5: Term Assurance | D5: Immediate | E5: 10 | F5: 35 | G5: Advance
B6: D | C6: Term Assurance | D6: Immediate | E6: 10 | F6: 40 | G6: Advance
B7: E | C7: Term Assurance | D7: Immediate | E7: 10 | F7: 45 | G7: Advance
B9: Sum Assured = | C9: 5000000 | I9: For Policyholder A
B11: Interest rate = | C11: 0.065
B12: Discount factor = | C12: =(1+i)^-1 -> 0.93896714 | H12: Mortality Table (IALM 2006-08)
H13: Year | I13: Age as per policy year | O13: Year | P13: Discounting factor | Q13: Probability survival | R13: EPV | S13: Term Assurance factor
B14: Initial Expense = | C14: 2000 | D14: (underwriting expense + medical examination fee) | H14: 0 | I14: =F3 -> 25 | J14: =VLOOKUP($I14,'IALM Comparison'!$AE$4:$AJ$118,2,FALSE) -> 0.000984 | K14: =VLOOKUP($I14,'IALM Comparison'!$AE$4:$AJ$118,3,FALSE) -> 9786.1973 | L14: =VLOOKUP($I14,'IALM Comparison'!$AE$4:$AJ$118,4,FALSE) -> 9.6296182 | M14: =VLOOKUP($I14,'IALM Comparison'!$AE$4:$AJ$118,5,FALSE) -> 0.999016 | O14: 0 | P14: =v^O14 -> 1 | Q14: 1 | R14: =Q14*P14 -> 1 | S14: =(S15*v)*(M14)+(v^0.5)*(L14/K14) -> 0.00779278
H15: 1 | I15: =I14+1 -> 26 | J15: =VLOOKUP($I15,'IALM Comparison'!$AE$4:$AJ$118,2,FALSE) -> 0.000994 | K15: =VLOOKUP($I15,'IALM Comparison'!$AE$4:$AJ$118,3,FALSE) -> 9776.5677 | L15: =VLOOKUP($I15,'IALM Comparison'!$AE$4:$AJ$118,4,FALSE) -> 9.7179083 | M15: =VLOOKUP($I15,'IALM Comparison'!$AE$4:$AJ$118,5,FALSE) -> 0.999006 | O15: 1 | P15: =v^O15 -> 0.93896714 | Q15: =Q14*M14 -> 0.999016 | R15: =Q15*P15 -> 0.93804319 | S15: =(S16*v)*(M15)+(v^0.5)*(L15/K15) -> 0.0072910085
H16: 2 | I16: =I15+1 -> 27 | J16: =VLOOKUP($I16,'IALM Comparison'!$AE$4:$AJ$118,2,FALSE) -> 0.001004 | K16: =VLOOKUP($I16,'IALM Comparison'!$AE$4:$AJ$118,3,FALSE) -> 9766.8498 | L16: =VLOOKUP($I16,'IALM Comparison'!$AE$4:$AJ$118,4,FALSE) -> 9.8059172 | M16: =VLOOKUP($I16,'IALM Comparison'!$AE$4:$AJ$118,5,FALSE) -> 0.998996 | O16: 2 | P16: =v^O16 -> 0.88165928 | Q16: =Q15*M15 -> 0.99802298 | R16: =Q16*P16 -> 0.87991622 | S16: =(S17*v)*(M16)+(v^0.5)*(L16/K16) -> 0.006745833
B17: Renewal Expense = | C17: 50 | D17: per subsequent premium | H17: 3 | I17: =I16+1 -> 28 | J17: =VLOOKUP($I17,'IALM Comparison'!$AE$4:$AJ$118,2,FALSE) -> 0.001017 | K17: =VLOOKUP($I17,'IALM Comparison'!$AE$4:$AJ$118,3,FALSE) -> 9757.0439 | L17: =VLOOKUP($I17,'IALM Comparison'!$AE$4:$AJ$118,4,FALSE) -> 9.9229136 | M17: =VLOOKUP($I17,'IALM Comparison'!$AE$4:$AJ$118,5,FALSE) -> 0.998983 | O17: 3 | P17: =v^O17 -> 0.82784909 | Q17: =Q16*M16 -> 0.99702096 | R17: =Q17*P17 -> 0.8253829 | S17: =(S18*v)*(M17)+(v^0.5)*(L17/K17) -> 0.0061543748
H18: 4 | I18: =I17+1 -> 29 | J18: =VLOOKUP($I18,'IALM Comparison'!$AE$4:$AJ$118,2,FALSE) -> 0.001034 | K18: =VLOOKUP($I18,'IALM Comparison'!$AE$4:$AJ$118,3,FALSE) -> 9747.121 | L18: =VLOOKUP($I18,'IALM Comparison'!$AE$4:$AJ$118,4,FALSE) -> 10.078523 | M18: =VLOOKUP($I18,'IALM Comparison'!$AE$4:$AJ$118,5,FALSE) -> 0.998966 | O18: 4 | P18: =v^O18 -> 0.77732309 | Q18: =Q17*M17 -> 0.99600699 | R18: =Q18*P18 -> 0.77421923 | S18: =(S19*v)*(M18)+(v^0.5)*(L18/K18) -> 0.0055104811
B19: Initial Commission = | C19: 1500 | H19: 5 | I19: =I18+1 -> 30 | J19: =VLOOKUP($I19,'IALM Comparison'!$AE$4:$AJ$118,2,FALSE) -> 0.001056 | K19: =VLOOKUP($I19,'IALM Comparison'!$AE$4:$AJ$118,3,FALSE) -> 9737.0425 | L19: =VLOOKUP($I19,'IALM Comparison'!$AE$4:$AJ$118,4,FALSE) -> 10.282317 | M19: =VLOOKUP($I19,'IALM Comparison'!$AE$4:$AJ$118,5,FALSE) -> 0.998944 | O19: 5 | P19: =v^O19 -> 0.72988084 | Q19: =Q18*M18 -> 0.99497712 | R19: =Q19*P19 -> 0.72621473 | S19: =(S20*v)*(M19)+(v^0.5)*(L19/K19) -> 0.0048065564
H20: 6 | I20: =I19+1 -> 31 | J20: =VLOOKUP($I20,'IALM Comparison'!$AE$4:$AJ$118,2,FALSE) -> 0.001084 | K20: =VLOOKUP($I20,'IALM Comparison'!$AE$4:$AJ$118,3,FALSE) -> 9726.7601 | L20: =VLOOKUP($I20,'IALM Comparison'!$AE$4:$AJ$118,4,FALSE) -> 10.543808 | M20: =VLOOKUP($I20,'IALM Comparison'!$AE$4:$AJ$118,5,FALSE) -> 0.998916 | O20: 6 | P20: =v^O20 -> 0.68533412 | Q20: =Q19*M19 -> 0.99392643 | R20: =Q20*P20 -> 0.68117169 | S20: =(S21*v)*(M20)+(v^0.5)*(L20/K20) -> 0.0040334622
B21: Renewal Commission = | C21: 40 | D21: per subsequent premium | H21: 7 | I21: =I20+1 -> 32 | J21: =VLOOKUP($I21,'IALM Comparison'!$AE$4:$AJ$118,2,FALSE) -> 0.001119 | K21: =VLOOKUP($I21,'IALM Comparison'!$AE$4:$AJ$118,3,FALSE) -> 9716.2163 | L21: =VLOOKUP($I21,'IALM Comparison'!$AE$4:$AJ$118,4,FALSE) -> 10.872446 | M21: =VLOOKUP($I21,'IALM Comparison'!$AE$4:$AJ$118,5,FALSE) -> 0.998881 | O21: 7 | P21: =v^O21 -> 0.64350621 | Q21: =Q20*M20 -> 0.99284901 | R21: =Q21*P21 -> 0.63890451 | S21: =(S22*v)*(M21)+(v^0.5)*(L21/K21) -> 0.0031804094
H22: 8 | I22: =I21+1 -> 33 | J22: =VLOOKUP($I22,'IALM Comparison'!$AE$4:$AJ$118,2,FALSE) -> 0.001164 | K22: =VLOOKUP($I22,'IALM Comparison'!$AE$4:$AJ$118,3,FALSE) -> 9705.3439 | L22: =VLOOKUP($I22,'IALM Comparison'!$AE$4:$AJ$118,4,FALSE) -> 11.29702 | M22: =VLOOKUP($I22,'IALM Comparison'!$AE$4:$AJ$118,5,FALSE) -> 0.998836 | O22: 8 | P22: =v^O22 -> 0.60423119 | Q22: =Q21*M21 -> 0.99173801 | R22: =Q22*P22 -> 0.59923904 | S22: =(S23*v)*(M22)+(v^0.5)*(L22/K22) -> 0.0022348418
H23: 9 | I23: =I22+1 -> 34 | J23: =VLOOKUP($I23,'IALM Comparison'!$AE$4:$AJ$118,2,FALSE) -> 0.001218 | K23: =VLOOKUP($I23,'IALM Comparison'!$AE$4:$AJ$118,3,FALSE) -> 9694.0469 | L23: =VLOOKUP($I23,'IALM Comparison'!$AE$4:$AJ$118,4,FALSE) -> 11.807349 | M23: =VLOOKUP($I23,'IALM Comparison'!$AE$4:$AJ$118,5,FALSE) -> 0.998782 | O23: 9 | P23: =v^O23 -> 0.56735323 | Q23: =Q22*M22 -> 0.99058363 | R23: =Q23*P23 -> 0.56201082 | S23: =(v^0.5)*(L23/K23) -> 0.0011802459
H24: 10 | I24: =I23+1 -> 35 | J24: =VLOOKUP($I24,'IALM Comparison'!$AE$4:$AJ$118,2,FALSE) -> 0.001282 | K24: =VLOOKUP($I24,'IALM Comparison'!$AE$4:$AJ$118,3,FALSE) -> 9682.2395 | L24: =VLOOKUP($I24,'IALM Comparison'!$AE$4:$AJ$118,4,FALSE) -> 12.412631 | M24: =VLOOKUP($I24,'IALM Comparison'!$AE$4:$AJ$118,5,FALSE) -> 0.998718 | O24: 10 | P24: 0 | Q24: =Q23*M23 -> 0.9893771 | R24: =Q24*P24 -> 0 | S24: 0
H26: Mortality Table (IALM 2012-14)
H27: Year | I27: Age as per policy year | O27: Year | P27: Discounting factor | Q27: Probability survival | R27: EPV | S27: Term Assurance factor
H28: 0 | I28: =F3 -> 25 | J28: =VLOOKUP($I28,'IALM Comparison'!$AL$4:$AQ$118,2,FALSE) -> 0.000931 | K28: =VLOOKUP($I28,'IALM Comparison'!$AL$4:$AQ$118,3,FALSE) -> 9866.5879 | L28: =VLOOKUP($I28,'IALM Comparison'!$AL$4:$AQ$118,4,FALSE) -> 9.1857933 | M28: =VLOOKUP($I28,'IALM Comparison'!$AL$4:$AQ$118,5,FALSE) -> 0.999069 | O28: 0 | P28: =v^O28 -> 1 | Q28: 1 | R28: =Q28*P28 -> 1 | S28: =(S29*v)*(M28)+(v^0.5)*(L28/K28) -> 0.0072648579
H29: 1 | I29: =I28+1 -> 26 | J29: =VLOOKUP($I29,'IALM Comparison'!$AL$4:$AQ$118,2,FALSE) -> 0.000931 | K29: =VLOOKUP($I29,'IALM Comparison'!$AL$4:$AQ$118,3,FALSE) -> 9857.4021 | L29: =VLOOKUP($I29,'IALM Comparison'!$AL$4:$AQ$118,4,FALSE) -> 9.1772414 | M29: =VLOOKUP($I29,'IALM Comparison'!$AL$4:$AQ$118,5,FALSE) -> 0.999069 | O29: 1 | P29: =v^O29 -> 0.93896714 | Q29: =Q28*M28 -> 0.999069 | R29: =Q29*P29 -> 0.93809296 | S29: =(S30*v)*(M29)+(v^0.5)*(L29/K29) -> 0.0067826071
H30: 2 | I30: =I29+1 -> 27 | J30: =VLOOKUP($I30,'IALM Comparison'!$AL$4:$AQ$118,2,FALSE) -> 0.000934 | K30: =VLOOKUP($I30,'IALM Comparison'!$AL$4:$AQ$118,3,FALSE) -> 9848.2249 | L30: =VLOOKUP($I30,'IALM Comparison'!$AL$4:$AQ$118,4,FALSE) -> 9.198242 | M30: =VLOOKUP($I30,'IALM Comparison'!$AL$4:$AQ$118,5,FALSE) -> 0.999066 | O30: 2 | P30: =v^O30 -> 0.88165928 | Q30: =Q29*M29 -> 0.99813887 | R30: =Q30*P30 -> 0.8800184 | S30: =(S31*v)*(M30)+(v^0.5)*(L30/K30) -> 0.0062685313
H31: 3 | I31: =I30+1 -> 28 | J31: =VLOOKUP($I31,'IALM Comparison'!$AL$4:$AQ$118,2,FALSE) -> 0.000942 | K31: =VLOOKUP($I31,'IALM Comparison'!$AL$4:$AQ$118,3,FALSE) -> 9839.0266 | L31: =VLOOKUP($I31,'IALM Comparison'!$AL$4:$AQ$118,4,FALSE) -> 9.2683631 | M31: =VLOOKUP($I31,'IALM Comparison'!$AL$4:$AQ$118,5,FALSE) -> 0.999058 | O31: 3 | P31: =v^O31 -> 0.82784909 | Q31: =Q30*M30 -> 0.99720661 | R31: =Q31*P31 -> 0.82553658 | S31: =(S32*v)*(M31)+(v^0.5)*(L31/K31) -> 0.0057174488
H32: 4 | I32: =I31+1 -> 29 | J32: =VLOOKUP($I32,'IALM Comparison'!$AL$4:$AQ$118,2,FALSE) -> 0.000956 | K32: =VLOOKUP($I32,'IALM Comparison'!$AL$4:$AQ$118,3,FALSE) -> 9829.7583 | L32: =VLOOKUP($I32,'IALM Comparison'!$AL$4:$AQ$118,4,FALSE) -> 9.3972489 | M32: =VLOOKUP($I32,'IALM Comparison'!$AL$4:$AQ$118,5,FALSE) -> 0.999044 | O32: 4 | P32: =v^O32 -> 0.77732309 | Q32: =Q31*M31 -> 0.99626724 | R32: =Q32*P32 -> 0.77442153 | S32: =(S33*v)*(M32)+(v^0.5)*(L32/K32) -> 0.0051217747
H33: 5 | I33: =I32+1 -> 30 | J33: =VLOOKUP($I33,'IALM Comparison'!$AL$4:$AQ$118,2,FALSE) -> 0.000977 | K33: =VLOOKUP($I33,'IALM Comparison'!$AL$4:$AQ$118,3,FALSE) -> 9820.361 | L33: =VLOOKUP($I33,'IALM Comparison'!$AL$4:$AQ$118,4,FALSE) -> 9.5944927 | M33: =VLOOKUP($I33,'IALM Comparison'!$AL$4:$AQ$118,5,FALSE) -> 0.999023 | O33: 5 | P33: =v^O33 -> 0.72988084 | Q33: =Q32*M32 -> 0.9953148 | R33: =Q33*P33 -> 0.7264612 | S33: =(S34*v)*(M33)+(v^0.5)*(L33/K33) -> 0.0044723847
H34: 6 | I34: =I33+1 -> 31 | J34: =VLOOKUP($I34,'IALM Comparison'!$AL$4:$AQ$118,2,FALSE) -> 0.001005 | K34: =VLOOKUP($I34,'IALM Comparison'!$AL$4:$AQ$118,3,FALSE) -> 9810.7665 | L34: =VLOOKUP($I34,'IALM Comparison'!$AL$4:$AQ$118,4,FALSE) -> 9.8598203 | M34: =VLOOKUP($I34,'IALM Comparison'!$AL$4:$AQ$118,5,FALSE) -> 0.998995 | O34: 6 | P34: =v^O34 -> 0.68533412 | Q34: =Q33*M33 -> 0.99434238 | R34: =Q34*P34 -> 0.68145676 | S34: =(S35*v)*(M34)+(v^0.5)*(L34/K34) -> 0.0037585092
H35: 7 | I35: =I34+1 -> 32 | J35: =VLOOKUP($I35,'IALM Comparison'!$AL$4:$AQ$118,2,FALSE) -> 0.001042 | K35: =VLOOKUP($I35,'IALM Comparison'!$AL$4:$AQ$118,3,FALSE) -> 9800.9067 | L35: =VLOOKUP($I35,'IALM Comparison'!$AL$4:$AQ$118,4,FALSE) -> 10.212545 | M35: =VLOOKUP($I35,'IALM Comparison'!$AL$4:$AQ$118,5,FALSE) -> 0.998958 | O35: 7 | P35: =v^O35 -> 0.64350621 | Q35: =Q34*M34 -> 0.99334307 | R35: =Q35*P35 -> 0.63922244 | S35: =(S36*v)*(M35)+(v^0.5)*(L35/K35) -> 0.0029686474
H36: 8 | I36: =I35+1 -> 33 | J36: =VLOOKUP($I36,'IALM Comparison'!$AL$4:$AQ$118,2,FALSE) -> 0.001086 | K36: =VLOOKUP($I36,'IALM Comparison'!$AL$4:$AQ$118,3,FALSE) -> 9790.6941 | L36: =VLOOKUP($I36,'IALM Comparison'!$AL$4:$AQ$118,4,FALSE) -> 10.632694 | M36: =VLOOKUP($I36,'IALM Comparison'!$AL$4:$AQ$118,5,FALSE) -> 0.998914 | O36: 8 | P36: =v^O36 -> 0.60423119 | Q36: =Q35*M35 -> 0.992308 | R36: =Q36*P36 -> 0.59958344 | S36: =(S37*v)*(M36)+(v^0.5)*(L36/K36) -> 0.0020884538
H37: 9 | I37: =I36+1 -> 34 | J37: =VLOOKUP($I37,'IALM Comparison'!$AL$4:$AQ$118,2,FALSE) -> 0.00114 | K37: =VLOOKUP($I37,'IALM Comparison'!$AL$4:$AQ$118,3,FALSE) -> 9780.0615 | L37: =VLOOKUP($I37,'IALM Comparison'!$AL$4:$AQ$118,4,FALSE) -> 11.14927 | M37: =VLOOKUP($I37,'IALM Comparison'!$AL$4:$AQ$118,5,FALSE) -> 0.99886 | O37: 9 | P37: =v^O37 -> 0.56735323 | Q37: =Q36*M36 -> 0.99123036 | R37: =Q37*P37 -> 0.56237774 | S37: =(v^0.5)*(L37/K37) -> 0.0011046636
H38: 10 | I38: =I37+1 -> 35 | J38: =VLOOKUP($I38,'IALM Comparison'!$AL$4:$AQ$118,2,FALSE) -> 0.001202 | K38: =VLOOKUP($I38,'IALM Comparison'!$AL$4:$AQ$118,3,FALSE) -> 9768.9122 | L38: =VLOOKUP($I38,'IALM Comparison'!$AL$4:$AQ$118,4,FALSE) -> 11.742232 | M38: =VLOOKUP($I38,'IALM Comparison'!$AL$4:$AQ$118,5,FALSE) -> 0.998798 | O38: 10 | P38: 0 | Q38: =Q37*M37 -> 0.99010036 | R38: =Q38*P38 -> 0 | S38: 0
I41: For Policyholder B
H44: Mortality Table (IALM 2006-08)
H45: Year | I45: Age as per policy year | O45: Year | P45: Discounting factor | Q45: Probability survival | R45: EPV | S45: Term Assurance factor
H46: 0 | I46: =F4 -> 30 | J46: =VLOOKUP($I46,'IALM Comparison'!$AE$4:$AJ$118,2,FALSE) -> 0.001056 | K46: =VLOOKUP($I46,'IALM Comparison'!$AE$4:$AJ$118,3,FALSE) -> 9737.0425 | L46: =VLOOKUP($I46,'IALM Comparison'!$AE$4:$AJ$118,4,FALSE) -> 10.282317 | M46: =VLOOKUP($I46,'IALM Comparison'!$AE$4:$AJ$118,5,FALSE) -> 0.998944 | O46: 0 | P46: =v^O46 -> 1 | Q46: 1 | R46: =Q46*P46 -> 1 | S46: =(S47*v)*(M46)+(v^0.5)*(L46/K46) -> 0.0093029472
H47: 1 | I47: =I46+1 -> 31 | J47: =VLOOKUP($I47,'IALM Comparison'!$AE$4:$AJ$118,2,FALSE) -> 0.001084 | K47: =VLOOKUP($I47,'IALM Comparison'!$AE$4:$AJ$118,3,FALSE) -> 9726.7601 | L47: =VLOOKUP($I47,'IALM Comparison'!$AE$4:$AJ$118,4,FALSE) -> 10.543808 | M47: =VLOOKUP($I47,'IALM Comparison'!$AE$4:$AJ$118,5,FALSE) -> 0.998916 | O47: 1 | P47: =v^O47 -> 0.93896714 | Q47: =Q46*M46 -> 0.998944 | R47: =Q47*P47 -> 0.93797559 | S47: =(S48*v)*(M47)+(v^0.5)*(L47/K47) -> 0.0088271806
H48: 2 | I48: =I47+1 -> 32 | J48: =VLOOKUP($I48,'IALM Comparison'!$AE$4:$AJ$118,2,FALSE) -> 0.001119 | K48: =VLOOKUP($I48,'IALM Comparison'!$AE$4:$AJ$118,3,FALSE) -> 9716.2163 | L48: =VLOOKUP($I48,'IALM Comparison'!$AE$4:$AJ$118,4,FALSE) -> 10.872446 | M48: =VLOOKUP($I48,'IALM Comparison'!$AE$4:$AJ$118,5,FALSE) -> 0.998881 | O48: 2 | P48: =v^O48 -> 0.88165928 | Q48: =Q47*M47 -> 0.99786114 | R48: =Q48*P48 -> 0.87977354 | S48: =(S49*v)*(M48)+(v^0.5)*(L48/K48) -> 0.0082912597
...

Sheet Pricing Term Assurance
B2: For Policyholder A | E2: For Policyholder B | H2: For Policyholder C | K2: For Policyholder D | N2: For Policyholder E
B6: Using IALM 2006-08 | E6: Using IALM 2006-08 | H6: Using IALM 2006-08 | K6: Using IALM 2006-08 | N6: Using IALM 2006-08
B7: Annuity Factor | C7: =SUM(Calculations!R14:R24) -> 7.6251023 | E7: Annuity Factor | F7: =SUM(Calculations!R46:R56) -> 7.6207314 | H7: Annuity Factor | I7: =SUM(Calculations!R78:R88) -> 7.6095073 | K7: Annuity Factor | L7: =SUM(Calculations!R110:R120) -> 7.5857897 | N7: Annuity Factor | O7: =SUM(Calculations!R142:R152) -> 7.5392349
B8: Term Assurance Factor | C8: =Calculations!S14 -> 0.00779278 | E8: Term Assurance Factor | F8: =Calculations!S46 -> 0.0093029472 | H8: Term Assurance Factor | I8: =Calculations!S78 -> 0.012831475 | K8: Term Assurance Factor | L8: =Calculations!S110 -> 0.020119274 | N8: Term Assurance Factor | O8: =Calculations!S142 -> 0.033426102
B10: EPV Benefit | C10: =C8*sum_assured -> 38963.9 | E10: EPV Benefit | F10: =sum_assured*F8 -> 46514.736 | H10: EPV Benefit | I10: =sum_assured*I8 -> 64157.375 | K10: EPV Benefit | L10: =sum_assured*L8 -> 100596.37 | N10: EPV Benefit | O10: =sum_assured*O8 -> 167130.51
B11: EPV Expenses | C11: =in_exp+re_exp*(C7-1) -> 2331.2551 | E11: EPV Expenses | F11: =in_exp+re_exp*(F7-1) -> 2331.0366 | H11: EPV Expenses | I11: =in_exp+re_exp*(I7-1) -> 2330.4754 | K11: EPV Expenses | L11: =in_exp+re_exp*(L7-1) -> 2329.2895 | N11: EPV Expenses | O11: =in_exp+re_exp*(O7-1) -> 2326.9617
B12: EPV Commission | C12: =in_com+re_com*(C7-1) -> 1765.0041 | E12: EPV Commission | F12: =in_com+re_com*(F7-1) -> 1764.8293 | H12: EPV Commission | I12: =in_com+re_com*(I7-1) -> 1764.3803 | K12: EPV Commission | L12: =in_com+re_com*(L7-1) -> 1763.4316 | N12: EPV Commission | O12: =in_com+re_com*(O7-1) -> 1761.5694
B14: Premium | C14: =SUM(C10:C12)/C7 -> 5647.1582 | E14: Premium | F14: =SUM(F10:F12)/F7 -> 6641.1739 | H14: Premium | I14: =SUM(I10:I12)/I7 -> 8969.3364 | K14: Premium | L14: =SUM(L10:L12)/L7 -> 13800.684 | N14: Premium | O14: =SUM(O10:O12)/O7 -> 22710.4
B17: Using IALM 2012-14 | E17: Using IALM 2012-14 | H17: Using IALM 2012-14 | K17: Using IALM 2012-14 | N17: Using IALM 2012-14
B18: Annuity Factor | C18: =SUM(Calculations!R28:R38) -> 7.6271711 | E18: Annuity Factor | F18: =SUM(Calculations!R60:R70) -> 7.6231411 | H18: Annuity Factor | I18: =SUM(Calculations!R92:R102) -> 7.6125362 | K18: Annuity Factor | L18: =SUM(Calculations!R124:R134) -> 7.5918928 | N18: Annuity Factor | O18: =SUM(Calculations!R156:R166) -> 7.5512803
B19: Term Assurance Factor | C19: =Calculations!S28 -> 0.0072648579 | E19: Term Assurance Factor | F19: =Calculations!S60 -> 0.0086912705 | H19: Term Assurance Factor | I19: =Calculations!S92 -> 0.011911616 | K19: Term Assurance Factor | L19: =Calculations!S124 -> 0.018197805 | N19: Term Assurance Factor | O19: =Calculations!S156 -> 0.030351212
B21: EPV Benefit | C21: =sum_assured*C19 -> 36324.289 | E21: EPV Benefit | F21: =sum_assured*F19 -> 43456.353 | H21: EPV Benefit | I21: =sum_assured*I19 -> 59558.078 | K21: EPV Benefit | L21: =sum_assured*L19 -> 90989.023 | N21: EPV Benefit | O21: =sum_assured*O19 -> 151756.06
B22: EPV Expenses | C22: =in_exp+re_exp*(C18-1) -> 2331.3586 | E22: EPV Expenses | F22: =in_exp+re_exp*(F18-1) -> 2331.1571 | H22: EPV Expenses | I22: =in_exp+re_exp*(I18-1) -> 2330.6268 | K22: EPV Expenses | L22: =in_exp+re_exp*(L18-1) -> 2329.5946 | N22: EPV Expenses | O22: =in_exp+re_exp*(O18-1) -> 2327.564
B23: EPV Commission | C23: =in_com+re_com*(C18-1) -> 1765.0868 | E23: EPV Commission | F23: =in_com+re_com*(F18-1) -> 1764.9256 | H23: EPV Commission | I23: =in_com+re_com*(I18-1) -> 1764.5014 | K23: EPV Commission | L23: =in_com+re_com*(L18-1) -> 1763.6757 | N23: EPV Commission | O23: =in_com+re_com*(O18-1) -> 1762.0512
B25: Premium | C25: =SUM(C21:C23)/C18 -> 5299.571 | E25: Premium | F25: =SUM(F21:F23)/F18 -> 6237.9057 | H25: Premium | I25: =SUM(I21:I23)/I18 -> 8361.6294 | K25: Premium | L25: =SUM(L21:L23)/L18 -> 12524.188 | N25: Premium | O25: =SUM(O21:O23)/O18 -> 20638.311

Sheet Premium Comparison
C2: Premium
C3: Policyholder | D3: IALM 2006-08 | E3: IALM 2012-14 | F3: ΔP | G3: Change % | H3: ΔP Benefit | I3: ΔP Renewal | J3: ΔP Denominator | K3: Residual
C4: A (25) | D4: ='Pricing Term Assurance'!C14 -> 5647.1582 | E4: ='Pricing Term Assurance'!C25 -> 5299.571 | F4: =E4-D4 -> -347.58718 | G4: =((D4-E4)/D4) -> 0.061550814 | H4: =(sum_assured*(a_asure_12-a_asure_06))/a_ann_06 -> -346.17381 | I4: =((re_exp+re_com)*(a_ann_12-a_ann_06))/a_ann_06 -> 0.024417314 | J4: =SUM('Pricing Term Assurance'!C10:C12)*(1/a_ann_12 - 1/a_ann_06) -> -1.5316782 | K4: =F4-H4-I4-J4 -> 0.093886066
C5: B (30) | D5: ='Pricing Term Assurance'!F14 -> 6641.1739 | E5: ='Pricing Term Assurance'!F25 -> 6237.9057 | F5: =E5-D5 -> -403.2682 | G5: =((D5-E5)/D5) -> 0.060722427 | H5: =(sum_assured*(b_asure_12-b_asure_06))/b_ann_06 -> -401.32415 | I5: =((re_exp+re_com)*(b_ann_12-b_ann_06))/b_ann_06 -> 0.028459106 | J5: =SUM('Pricing Term Assurance'!F10:F12)*(1/b_ann_12 - 1/b_ann_06) -> -2.0993569 | K5: =F5-H5-I5-J5 -> 0.12685452
C6: C (35) | D6: ='Pricing Term Assurance'!I14 -> 8969.3364 | E6: ='Pricing Term Assurance'!I25 -> 8361.6294 | F6: =E6-D6 -> -607.70703 | G6: =((D6-E6)/D6) -> 0.067753845 | H6: =(sum_assured*(c_asure_12-c_asure_06))/c_ann_06 -> -604.41458 | I6: =((re_exp+re_com)*(c_ann_12-c_ann_06))/c_ann_06 -> 0.035823707 | J6: =SUM('Pricing Term Assurance'!I10:I12)*(1/c_ann_12 - 1/c_ann_06) -> -3.5687448 | K6: =F6-H6-I6-J6 -> 0.24047192
C7: D (40) | D7: ='Pricing Term Assurance'!L14 -> 13800.684 | E7: ='Pricing Term Assurance'!L25 -> 12524.188 | F7: =E7-D7 -> -1276.4963 | G7: =((D7-E7)/D7) -> 0.092495148 | H7: =(sum_assured*(d_asure_12-d_asure_06))/d_ann_06 -> -1266.4926 | I7: =((re_exp+re_com)*(d_ann_12-d_ann_06))/d_ann_06 -> 0.072408278 | J7: =SUM('Pricing Term Assurance'!L10:L12)*(1/d_ann_12 - 1/d_ann_06) -> -11.094228 | K7: =F7-H7-I7-J7 -> 1.0180621
C8: E (45) | D8: ='Pricing Term Assurance'!O14 -> 22710.4 | E8: ='Pricing Term Assurance'!O25 -> 20638.311 | F8: =E8-D8 -> -2072.0889 | G8: =((D8-E8)/D8) -> 0.091239648 | H8: =(sum_assured*(e_asure_12-e_asure_06))/e_ann_06 -> -2039.259 | I8: =((re_exp+re_com)*(e_ann_12-e_ann_06))/e_ann_06 -> 0.14379264 | J8: =SUM('Pricing Term Assurance'!O10:O12)*(1/e_ann_12 - 1/e_ann_06) -> -36.226436 | K8: =F8-H8-I8-J8 -> 3.2526893
C9: % of Total | F9: =ABS(SUM(F4:F8))/ABS(SUM(F4:F8)) -> 1 | H9: =ABS(SUM(H4:H8))/ABS(SUM($F$4:$F$8)) -> 0.98948757 | I9: =SUM(I4:I8)/ABS(SUM($F$4:$F$8)) -> 6.4774055e-05 | J9: =ABS(SUM(J4:J8))/ABS(SUM($F$4:$F$8)) -> 0.01158248 | K9: =ABS(SUM(K4:K8))/ABS(SUM($F$4:$F$8)) -> 0.001005272
L22: Mortality Improvement between IALM 2006-08 and IALM 2012-14 reduced gross premiums by 6.1% to 9.3% across the entry ages 25-45. The reduction is largest at older entry ages, reflecting greater absolute mortality improvement at ages 40-45. Over 98.95% of premium reduction is attributable to the lower EPV of Benefit. Expense and denominator effects are negligible.

Sheet Stress Test on IALM 2012-14
B2: Age = | C2: 35 | D2: <- dropdown | W2: Premium sensitivity to a ±10% mortality is approximately ±9% across all ages. Interest rate sensitivity is lower - a ±1% shift in discount rate moves premium by less than ±0.2%. This confirms that mortality assumption risk dominates interest rate risk for short-term assurance pricing
B3: Stress factor = | C3: 1 | D3: <- dropdown | T3: Selected age | U3: =C2 -> 35
B4: Interest = | C4: 0.065 | D4: <- dropdown
B5: Discount factor = | C5: =(1+C4)^-1 -> 0.93896714 | S5: Mortality Stress | T5: Stress Factor | U5: =H28 -> 8361.6294 | V5: vs Base Premium | W5: vs Base Premium % | Z5: Interest rate stress | AA5: Stress rate | AB5: =H28 -> 8361.6294 | AC5: vs Base Premium | AD5: vs Base Premium (%)
T6: 0.75 | U6: 6406.4964 | V6: =U6-VLOOKUP($U$3,$B$9:$C$13,2,FALSE) -> -1955.133 | W6: =(U6-VLOOKUP($U$3,$B$9:$C$13,2,FALSE))/VLOOKUP($U$3,$B$9:$C$13,2,FALSE) -> -0.23382201 | AA6: 0.055 | AB6: 8427.4162 | AC6: =AB6-$H$28 -> 65.786844 | AD6: =(AB6-$H$28)/$H$28 -> 0.0078677063
B7: Base Premium rates | F7: Mortality Table (IALM 2012-14) | T7: 0.8 | U7: 6797.599 | V7: =U7-VLOOKUP($U$3,$B$9:$C$13,2,FALSE) -> -1564.0304 | W7: =(U7-VLOOKUP($U$3,$B$9:$C$13,2,FALSE))/VLOOKUP($U$3,$B$9:$C$13,2,FALSE) -> -0.18704852 | AA7: 0.06 | AB7: 8394.2777 | AC7: =AB7-$H$28 -> 32.648348 | AD7: =(AB7-$H$28)/$H$28 -> 0.0039045438
B8: Age | C8: Premium | F8: Year | G8: Age as per policy year | M8: Year | N8: Discounting factor | O8: Probability survival | P8: EPV | Q8: Term Assurance factor | T8: 0.85 | U8: 7188.6636 | V8: =U8-VLOOKUP($U$3,$B$9:$C$13,2,FALSE) -> -1172.9658 | W8: =(U8-VLOOKUP($U$3,$B$9:$C$13,2,FALSE))/VLOOKUP($U$3,$B$9:$C$13,2,FALSE) -> -0.14027957 | AA8: 0.065 | AB8: 8361.6294 | AC8: =AB8-$H$28 -> 0 | AD8: =(AB8-$H$28)/$H$28 -> 0
B9: =Calculations!F3 -> 25 | C9: ='Pricing Term Assurance'!C25 -> 5299.571 | F9: 0 | G9: =C2 -> 35 | H9: =VLOOKUP($G9,'IALM Comparison'!$AL$4:$AQ$118,2,FALSE)*$C$3 -> 0.001202 | I9: 10000 | J9: =I9*H9 -> 12.02 | K9: =1-H9 -> 0.998798 | M9: 0 | N9: =$C$5^M9 -> 1 | O9: 1 | P9: =O9*N9 -> 1 | Q9: =(Q10*$C$5)*(K9)+($C$5^0.5)*(J9/I9) -> 0.011911616 | T9: 0.9 | U9: 7579.6902 | V9: =U9-VLOOKUP($U$3,$B$9:$C$13,2,FALSE) -> -781.93919 | W9: =(U9-VLOOKUP($U$3,$B$9:$C$13,2,FALSE))/VLOOKUP($U$3,$B$9:$C$13,2,FALSE) -> -0.09351517 | AA9: 0.07 | AB9: 8329.4669 | AC9: =AB9-$H$28 -> -32.162519 | AD9: =(AB9-$H$28)/$H$28 -> -0.0038464416
B10: =Calculations!F4 -> 30 | C10: ='Pricing Term Assurance'!F25 -> 6237.9057 | F10: 1 | G10: =G9+1 -> 36 | H10: =VLOOKUP($G10,'IALM Comparison'!$AL$4:$AQ$118,2,FALSE)*$C$3 -> 0.001275 | I10: =I9-J9 -> 9987.98 | J10: =I10*H10 -> 12.734675 | K10: =1-H10 -> 0.998725 | M10: 1 | N10: =$C$5^M10 -> 0.93896714 | O10: =O9*K9 -> 0.998798 | P10: =O10*N10 -> 0.9378385 | Q10: =(Q11*$C$5)*(K10)+($C$5^0.5)*(J10/I10) -> 0.011459194 | T10: 1 | U10: 8361.6294 | V10: =U10-VLOOKUP($U$3,$B$9:$C$13,2,FALSE) -> 0 | W10: =(U10-VLOOKUP($U$3,$B$9:$C$13,2,FALSE))/VLOOKUP($U$3,$B$9:$C$13,2,FALSE) -> 0 | AA10: 0.075 | AB10: 8297.7858 | AC10: =AB10-$H$28 -> -63.843639 | AD10: =(AB10-$H$28)/$H$28 -> -0.0076353107
B11: =Calculations!F5 -> 35 | C11: ='Pricing Term Assurance'!I25 -> 8361.6294 | F11: 2 | G11: =G10+1 -> 37 | H11: =VLOOKUP($G11,'IALM Comparison'!$AL$4:$AQ$118,2,FALSE)*$C$3 -> 0.001358 | I11: =I10-J10 -> 9975.2453 | J11: =I11*H11 -> 13.546383 | K11: =1-H11 -> 0.998642 | M11: 2 | N11: =$C$5^M11 -> 0.88165928 | O11: =O10*K10 -> 0.99752453 | P11: =O11*N11 -> 0.87947676 | Q11: =(Q12*$C$5)*(K11)+($C$5^0.5)*(J11/I11) -> 0.010902157 | T11: 1.1 | U11: 9143.4166 | V11: =U11-VLOOKUP($U$3,$B$9:$C$13,2,FALSE) -> 781.78723 | W11: =(U11-VLOOKUP($U$3,$B$9:$C$13,2,FALSE))/VLOOKUP($U$3,$B$9:$C$13,2,FALSE) -> 0.093496996
B12: =Calculations!F6 -> 40 | C12: ='Pricing Term Assurance'!L25 -> 12524.188 | F12: 3 | G12: =G11+1 -> 38 | H12: =VLOOKUP($G12,'IALM Comparison'!$AL$4:$AQ$118,2,FALSE)*$C$3 -> 0.001453 | I12: =I11-J11 -> 9961.6989 | J12: =I12*H12 -> 14.474349 | K12: =1-H12 -> 0.998547 | M12: 3 | N12: =$C$5^M12 -> 0.82784909 | O12: =O11*K11 -> 0.99616989 | P12: =O12*N12 -> 0.82467834 | Q12: =(Q13*$C$5)*(K12)+($C$5^0.5)*(J12/I12) -> 0.01022324 | T12: 1.15 | U12: 9534.2533 | V12: =U12-VLOOKUP($U$3,$B$9:$C$13,2,FALSE) -> 1172.6239 | W12: =(U12-VLOOKUP($U$3,$B$9:$C$13,2,FALSE))/VLOOKUP($U$3,$B$9:$C$13,2,FALSE) -> 0.14023868
B13: =Calculations!F7 -> 45 | C13: ='Pricing Term Assurance'!O25 -> 20638.311 | F13: 4 | G13: =G12+1 -> 39 | H13: =VLOOKUP($G13,'IALM Comparison'!$AL$4:$AQ$118,2,FALSE)*$C$3 -> 0.00156 | I13: =I12-J12 -> 9947.2246 | J13: =I13*H13 -> 15.51767 | K13: =1-H13 -> 0.99844 | M13: 4 | N13: =$C$5^M13 -> 0.77732309 | O13: =O12*K12 -> 0.99472246 | P13: =O13*N13 -> 0.77322074 | Q13: =(Q14*$C$5)*(K13)+($C$5^0.5)*(J13/I13) -> 0.0094019329 | T13: 1.2 | U13: 9925.0519 | V13: =U13-VLOOKUP($U$3,$B$9:$C$13,2,FALSE) -> 1563.4225 | W13: =(U13-VLOOKUP($U$3,$B$9:$C$13,2,FALSE))/VLOOKUP($U$3,$B$9:$C$13,2,FALSE) -> 0.18697582
F14: 5 | G14: =G13+1 -> 40 | H14: =VLOOKUP($G14,'IALM Comparison'!$AL$4:$AQ$118,2,FALSE)*$C$3 -> 0.00168 | I14: =I13-J13 -> 9931.7069 | J14: =I14*H14 -> 16.685268 | K14: =1-H14 -> 0.99832 | M14: 5 | N14: =$C$5^M14 -> 0.72988084 | O14: =O13*K13 -> 0.99317069 | P14: =O14*N14 -> 0.72489626 | Q14: =(Q15*$C$5)*(K14)+($C$5^0.5)*(J14/I14) -> 0.0084162861 | T14: 1.25 | U14: 10315.813 | V14: =U14-VLOOKUP($U$3,$B$9:$C$13,2,FALSE) -> 1954.1832 | W14: =(U14-VLOOKUP($U$3,$B$9:$C$13,2,FALSE))/VLOOKUP($U$3,$B$9:$C$13,2,FALSE) -> 0.23370842
F15: 6 | G15: =G14+1 -> 41 | H15: =VLOOKUP($G15,'IALM Comparison'!$AL$4:$AQ$118,2,FALSE)*$C$3 -> 0.001815 | I15: =I14-J14 -> 9915.0217 | J15: =I15*H15 -> 17.995764 | K15: =1-H15 -> 0.998185 | M15: 6 | N15: =$C$5^M15 -> 0.68533412 | O15: =O14*K14 -> 0.99150217 | P15: =O15*N15 -> 0.67951026 | Q15: =(Q16*$C$5)*(K15)+($C$5^0.5)*(J15/I15) -> 0.0072417704
F16: 7 | G16: =G15+1 -> 42 | H16: =VLOOKUP($G16,'IALM Comparison'!$AL$4:$AQ$118,2,FALSE)*$C$3 -> 0.001969 | I16: =I15-J15 -> 9897.0259 | J16: =I16*H16 -> 19.487244 | K16: =1-H16 -> 0.998031 | M16: 7 | N16: =$C$5^M16 -> 0.64350621 | O16: =O15*K15 -> 0.98970259 | P16: =O16*N16 -> 0.63687977 | Q16: =(Q17*$C$5)*(K16)+($C$5^0.5)*(J16/I16) -> 0.0058500444
F17: 8 | G17: =G16+1 -> 43 | H17: =VLOOKUP($G17,'IALM Comparison'!$AL$4:$AQ$118,2,FALSE)*$C$3 -> 0.002144 | I17: =I16-J16 -> 9877.5386 | J17: =I17*H17 -> 21.177443 | K17: =1-H17 -> 0.997856 | M17: 8 | N17: =$C$5^M17 -> 0.60423119 | O17: =O16*K16 -> 0.98775386 | P17: =O17*N17 -> 0.59683169 | Q17: =(Q18*$C$5)*(K17)+($C$5^0.5)*(J17/I17) -> 0.004206595
F18: 9 | G18: =G17+1 -> 44 | H18: =VLOOKUP($G18,'IALM Comparison'!$AL$4:$AQ$118,2,FALSE)*$C$3 -> 0.002345 | I18: =I17-J17 -> 9856.3612 | J18: =I18*H18 -> 23.113167 | K18: =1-H18 -> 0.997655 | M18: 9 | N18: =$C$5^M18 -> 0.56735323 | O18: =O17*K17 -> 0.98563612 | P18: =O18*N18 -> 0.55920383 | Q18: =($C$5^0.5)*(J18/I18) -> 0.0022723124
F19: 10 | G19: =G18+1 -> 45 | H19: =VLOOKUP($G19,'IALM Comparison'!$AL$4:$AQ$118,2,FALSE)*$C$3 -> 0.002579 | I19: =I18-J18 -> 9833.248 | J19: =I19*H19 -> 25.359947 | K19: =1-H19 -> 0.997421 | M19: 10 | N19: 0 | O19: =O18*K18 -> 0.9833248 | P19: 0 | Q19: 0
F21: Premium Calculation | G21: Annuity factor | H21: =SUM(P9:P18) -> 7.6125362
G22: Assurance Factor | H22: =Q9 -> 0.011911616
G24: EPV Benefit | H24: =sum_assured*H22 -> 59558.078
G25: EPV Expenses | H25: =in_exp+re_exp*(H21-1) -> 2330.6268
G26: EPV Commission | H26: =in_com+re_com*(H21-1) -> 1764.5014
G28: Premium | H28: =SUM(H24:H26)/H21 -> 8361.6294
